Workbook
Name feb_11: Comentarios!$A$106

Sheet Índice
A1: Banco Central del Uruguay
A2: Superintendencia de Servicios Financieros
A5: CRÉDITOS BRUTOS SECTOR NO FINANCIERO (SNF)
A8: Bancos públicos
A9: Bancos privados
A10: Cooperativas de intermediación financiera
A11: Casas financieras
A12: Total Sistema Bancario
A13: Instituciones financieras externas (IFEs)
A14: Empresas administradoras de créditos (EACs)
A15: Comentarios

Sheet Bcos. Públ.
A1: Banco Central del Uruguay | T1: Banco Central del Uruguay
A2: Superintendencia de Servicios Financieros | T2: Superintendencia de Instituciones de Intermediación Financiera
M3: Volver al Índice | AH3: Volver al Índice
B4: CRÉDITOS BRUTOS SECTOR NO FINANCIERO (SNF) (1) | T4: CRÉDITOS BRUTOS SNF (1) - ANEXO RESIDENTES POR MONEDAS
B5: BANCOS PÚBLICOS | T5: BANCOS PÚBLICOS
B6: (Crédito Total en millones de pesos) | T6: (Créditos en MN en millones de pesos y en ME en millones de dólares)
B8: TOTAL (MN + ME) en millones de pesos
B9: RESIDENTES | K9: NO RESIDENTES (4) | N9: TOTAL | Q9: Variación mensual | T9: MONEDA NACIONAL en millones de pesos | AD9: MONEDA EXTRANJERA en millones de dólares
A10: Mes | B10: SECTOR PRIVADO (2) | E10: SECTOR PÚBLICO (3) | H10: TOTAL (S.Priv. + S.Públ) | Q10: Castigados (1) | T10: SECTOR PRIVADO (2) | W10: SECTOR PÚBLICO (3) | Z10: TOTAL (S.Priv. + S.Públ) | AC10: Variac. mens. | AD10: SECTOR PRIVADO (2) | AG10: SECTOR PÚBLICO (3) | AJ10: TOTAL (S.Priv. + S.Públ) | AM10: Variac. mens.
B11: Vigentes | C11: Vencidos | D11: Total | E11: Vigentes | F11: Vencidos | G11: Total | H11: Vigentes | I11: Vencidos | J11: Total | K11: Vigentes | L11: Vencidos | M11: Total | N11: Vigentes | O11: Vencidos | P11: Total | Q11: Resid. | R11: No resid. | T11: Vigentes | U11: Vencidos | V11: Total | W11: Vigentes | X11: Vencidos | Y11: Total | Z11: Vigentes | AA11: Vencidos | AB11: Total | AC11: Castigados (1) | AD11: Vigentes | AE11: Vencidos | AF11: Total | AG11: Vigentes | AH11: Vencidos | AI11: Total | AJ11: Vigentes | AK11: Vencidos | AL11: Total | AM11: Castigados (1)
A12: 36130 | B12: 44306.432 | C12: 11703.994 | D12: 55999.609 | E12: 8502.162 | F12: 162.255 | G12: 8664.417 | H12: 52797.777 | I12: 11866.249 | J12: 64664.026 | K12: 0 | L12: 0 | M12: 0 | N12: 52797.777 | O12: 11866.249 | P12: 64664.026 | Q12: 1.6328268 | R12: 0 | T12: 25495.669 | U12: 5505.853 | V12: 31001.522 | W12: 4359.251 | X12: 0 | Y12: 4359.251 | Z12: 29854.92 | AA12: 5505.853 | AB12: 35360.773 | AC12: 1.6328268 | AD12: 1738 | AE12: 573 | AF12: 2311 | AG12: 383 | AH12: 15 | AI12: 398 | AJ12: 2121 | AK12: 588 | AL12: 2709 | AM12: 0
A13: 36161 | B13: 43825.15 | C13: 12999.45 | D13: 56824.6 | E13: 8556.6 | F13: 164.55 | G13: 8721.15 | H13: 52381.75 | I13: 13164 | J13: 65545.75 | K13: 0 | L13: 0 | M13: 0 | N13: 52381.75 | O13: 13164 | P13: 65545.75 | Q13: 0.57398156 | R13: 0 | T13: 24638.62 | U13: 6571.03 | V13: 31209.65 | W13: 4398.97 | X13: 0 | Y13: 4398.97 | Z13: 29048.56 | AA13: 6571.03 | AB13: 35608.62 | AC13: 0.57398156 | AD13: 1748 | AE13: 587 | AF13: 2335 | AG13: 379 | AH13: 15 | AI13: 394 | AJ13: 2127 | AK13: 602 | AL13: 2729 | AM13: 0
A14: 36192 | B14: 43994.925 | C14: 13324.805 | D14: 57330.715 | E14: 8568.3 | F14: 164.775 | G14: 8733.075 | H14: 52563.225 | I14: 13500.565 | J14: 66063.79 | K14: 0 | L14: 0 | M14: 0 | N14: 52563.225 | O14: 13500.565 | P14: 66063.79 | Q14: 0.69165361 | R14: 0 | T14: 24672.31 | U14: 6821.685 | V14: 31493.995 | W14: 4437.94 | X14: 0 | Y14: 4437.94 | Z14: 29110.25 | AA14: 6821.685 | AB14: 35942.92 | AC14: 0.69165361 | AD14: 1759 | AE14: 592 | AF14: 2351 | AG14: 376 | AH14: 15 | AI14: 391 | AJ14: 2135 | AK14: 607 | AL14: 2742 | AM14: 0
A15: 36220 | B15: 45156.65 | C15: 13436.045 | D15: 58592.695 | E15: 8687.385 | F15: 177.52 | G15: 8864.905 | H15: 53844.035 | I15: 13613.565 | J15: 67457.6 | K15: 0 | L15: 0 | M15: 0 | N15: 53844.035 | O15: 13613.565 | P15: 67457.6 | Q15: 2.1017909 | R15: 0 | T15: 25662.735 | U15: 6424.005 | V15: 32086.74 | W15: 4482.38 | X15: 0 | Y15: 4482.38 | Z15: 30134.02 | AA15: 6435.1 | AB15: 36569.12 | AC15: 2.1017909 | AD15: 1757 | AE15: 632 | AF15: 2389 | AG15: 379 | AH15: 15 | AI15: 395 | AJ15: 2137 | AK15: 647 | AL15: 2784 | AM15: 0
A16: 36251 | B16: 45708.586 | C16: 13104.168 | D16: 58812.754 | E16: 8736.112 | F16: 178.288 | G16: 8903.257 | H16: 54433.555 | I16: 13282.456 | J16: 67716.011 | K16: 0 | L16: 0 | M16: 0 | N16: 54433.555 | O16: 13282.456 | P16: 67716.011 | Q16: 2.243071 | R16: 0 | T16: 26152.621 | U16: 6106.364 | V16: 32258.985 | W16: 4501.772 | X16: 0 | Y16: 4512.915 | Z16: 30654.393 | AA16: 6117.507 | AB16: 36760.757 | AC16: 2.243071 | AD16: 1755 | AE16: 628 | AF16: 2383 | AG16: 379 | AH16: 15 | AI16: 395 | AJ16: 2134 | AK16: 643 | AL16: 2778 | AM16: 0
A17: 36281 | B17: 46003.23 | C17: 13252.512 | D17: 59255.742 | E17: 8775.312 | F17: 190.281 | G17: 8965.593 | H17: 54778.542 | I17: 13453.986 | J17: 68221.335 | K17: 0 | L17: 0 | M17: 0 | N17: 54778.542 | O17: 13453.986 | P17: 68221.335 | Q17: 0.86793852 | R17: 0 | T17: 26426.673 | U17: 6044.22 | V17: 32470.893 | W17: 4555.551 | X17: 0 | Y17: 4555.551 | Z17: 30982.224 | AA17: 6044.22 | AB17: 37026.444 | AC17: 0.86793852 | AD17: 1748 | AE17: 645 | AF17: 2393 | AG17: 377 | AH17: 17 | AI17: 394 | AJ17: 2126 | AK17: 662 | AL17: 2787 | AM17: 0
A18: 36312 | B18: 46882.633 | C18: 13417.78 | D18: 60311.784 | E18: 8755.67 | F18: 216.049 | G18: 8971.719 | H18: 55638.303 | I18: 13645.2 | J18: 69283.503 | K18: 0 | L18: 0 | M18: 0 | N18: 55638.303 | O18: 13645.2 | P18: 69283.503 | Q18: 1.8931953 | R18: 0 | T18: 26721.85 | U18: 5969.775 | V18: 32691.625 | W18: 4537.029 | X18: 0 | Y18: 4548.4 | Z18: 31258.879 | AA18: 5969.775 | AB18: 37228.654 | AC18: 1.8931953 | AD18: 1773 | AE18: 656 | AF18: 2429 | AG18: 371 | AH18: 19 | AI18: 390 | AJ18: 2144 | AK18: 675 | AL18: 2819 | AM18: 0
A19: 36342 | B19: 46954.5 | C19: 13811.5 | D19: 60754.5 | E19: 8786 | F19: 230 | G19: 9016 | H19: 55729 | I19: 14030 | J19: 69770.5 | K19: 0 | L19: 0 | M19: 0 | N19: 55740.5 | O19: 14030 | P19: 69770.5 | Q19: 1.2994424 | R19: 0 | T19: 26726 | U19: 6141 | V19: 32855.5 | W19: 4542.5 | X19: 0 | Y19: 4542.5 | Z19: 31257 | AA19: 6141 | AB19: 37409.5 | AC19: 1.2994424 | AD19: 1759 | AE19: 667 | AF19: 2426 | AG19: 369 | AH19: 19 | AI19: 389 | AJ19: 2128 | AK19: 686 | AL19: 2814 | AM19: 0
A20: 36373 | B20: 45341.855 | C20: 15934.39 | D20: 61276.245 | E20: 8947.055 | F20: 198.305 | G20: 9145.36 | H20: 54288.91 | I20: 16132.695 | J20: 70421.605 | K20: 0 | L20: 0 | M20: 0 | N20: 54288.91 | O20: 16132.695 | P20: 70421.605 | Q20: 2.9443771 | R20: 0 | T20: 25068.085 | U20: 7920.535 | V20: 32976.955 | W20: 4549.35 | X20: 0 | Y20: 4561.015 | Z20: 29617.435 | AA20: 7920.535 | AB20: 37537.97 | AC20: 2.9443771 | AD20: 1738 | AE20: 687 | AF20: 2426 | AG20: 377 | AH20: 17 | AI20: 393 | AJ20: 2115 | AK20: 704 | AL20: 2819 | AM20: 0
A21: 36404 | B21: 45404.04 | C21: 16440.6 | D21: 61856.3 | E21: 9024.84 | F21: 198.22 | G21: 9223.06 | H21: 54440.54 | I21: 16638.82 | J21: 71079.36 | K21: 0 | L21: 0 | M21: 0 | N21: 54440.54 | O21: 16638.82 | P21: 71079.36 | Q21: 2.6148383 | R21: 0 | T21: 25162.28 | U21: 8231.96 | V21: 33394.24 | W21: 4594.04 | X21: 0 | Y21: 4594.04 | Z21: 29756.32 | AA21: 8231.96 | AB21: 37988.28 | AC21: 2.6148383 | AD21: 1736 | AE21: 705 | AF21: 2441 | AG21: 381 | AH21: 17 | AI21: 397 | AJ21: 2117 | AK21: 721 | AL21: 2838 | AM21: 0
A22: 36434 | B22: 45493.24 | C22: 17019.47 | D22: 62501.14 | E22: 9059.31 | F22: 104.13 | G22: 9163.44 | H22: 54552.55 | I22: 17123.6 | J22: 71664.58 | K22: 0 | L22: 0 | M22: 0 | N22: 54552.55 | O22: 17123.6 | P22: 71664.58 | Q22: 2.5934455 | R22: 0 | T22: 25106.9 | U22: 8538.66 | V22: 33645.56 | W22: 4604.86 | X22: 0 | Y22: 4604.86 | Z22: 29711.76 | AA22: 8538.66 | AB22: 38250.42 | AC22: 2.5934455 | AD22: 1762 | AE22: 733 | AF22: 2495 | AG22: 386 | AH22: 9 | AI22: 394 | AJ22: 2147 | AK22: 742 | AL22: 2889 | AM22: 0
A23: 36465 | B23: 45133.492 | C23: 17438.99 | D23: 62572.482 | E23: 9273.847 | F23: 196.333 | G23: 9470.18 | H23: 54407.339 | I23: 17635.323 | J23: 72042.662 | K23: 0 | L23: 0 | M23: 0 | N23: 54407.339 | O23: 17635.323 | P23: 72042.662 | Q23: 0.63406123 | R23: 0 | T23: 25165.271 | U23: 8742.593 | V23: 33919.413 | W23: 4688.894 | X23: 11.549 | Y23: 4688.894 | Z23: 29854.165 | AA23: 8754.142 | AB23: 38608.307 | AC23: 0.63406123 | AD23: 1728 | AE23: 753 | AF23: 2481 | AG23: 397 | AH23: 16 | AI23: 414 | AJ23: 2126 | AK23: 769 | AL23: 2895 | AM23: 0
... A251: 43405 | B251: 187631.32 | C251: 9394.5431 | D251: 197025.86 | E251: 13345.872 | F251: 0.10981809 | G251: 13345.981 | H251: 200977.19 | I251: 9394.6529 | J251: 210371.84 | K251: 10.882262 | L251: 1.1936797 | M251: 12.075942 | N251: 200988.07 | O251: 9395.8466 | P251: 210383.92 | Q251: 1149.6303 | R251: 0.042724284 | T251: 127807.55 | U251: 3578.5619 | V251: 131386.11 | W251: 12267.444 | X251: 0.08984978 | Y251: 12267.534 | Z251: 140074.99 | AA251: 3578.6518 | AB251: 143653.65 | AC251: 278.11462 | AD251: 1858.9779 | AE251: 180.72717 | AF251: 2039.7051 | AG251: 33.511316 | AH251: 0.0006205 | AI251: 33.511936 | AJ251: 1892.4892 | AK251: 180.72779 | AL251: 2073.217 | AM251: 27.081684
A252: 43435 | B252: 191798.11 | C252: 9190.1422 | D252: 200988.25 | E252: 9631.1852 | F252: 0.12998941 | G252: 9631.3152 | H252: 201429.3 | I252: 9190.2722 | J252: 210619.57 | K252: 12.638478 | L252: 1.5471441 | M252: 14.185622 | N252: 201441.93 | O252: 9191.8193 | P252: 210633.75 | Q252: 596.54286 | R252: 0.11455039 | T252: 132264.48 | U252: 3479.317 | V252: 135743.8 | W252: 8536.7302 | X252: 0.10621159 | Y252: 8536.8364 | Z252: 140801.21 | AA252: 3479.4232 | AB252: 144280.63 | AC252: 361.35869 | AD252: 1838.0251 | AE252: 176.31446 | AF252: =+AE252+AD252 -> 2014.3395 | AG252: 33.789905 | AH252: 0.00073411 | AI252: =+AH252+AG252 -> 33.790639 | AJ252: 1871.815 | AK252: 176.31519 | AL252: =+AK252+AJ252 -> 2048.1302 | AM252: 7.2610117
A253: 43467 | B253: 189201.63 | C253: 7491.2371 | D253: 196692.87 | E253: 9533.3084 | F253: 0.17288911 | G253: 9533.4813 | H253: 198734.94 | I253: 7491.41 | J253: 206226.35 | K253: 59.322501 | L253: 5.1714979 | M253: 64.493999 | N253: 198794.26 | O253: 7496.5815 | P253: 206290.85 | Q253: ND | R253: ND | T253: 130774.68 | U253: 3574.4275 | V253: 134349.08 | W253: 8433.9393 | X253: 0.14533504 | Y253: 8434.0847 | Z253: 139208.62 | AA253: 3574.5729 | AB253: 142783.19 | AC253: ND | AD253: 1800.9632 | AE253: 120.76924 | AF253: 1921.7324 | AG253: 33.627225 | AH253: 0.00084847 | AI253: 33.628074 | AJ253: 1834.5904 | AK253: 120.77009 | AL253: 1955.3605 | AM253: ND
A254: 43497 | B254: 190582.56 | C254: 7785.2639 | D254: 198367.83 | E254: 8808.302 | F254: 0.14307211 | G254: 8808.4451 | H254: 199390.86 | I254: 7785.407 | J254: 207176.27 | K254: 54.671969 | L254: 8.0468612 | M254: 62.71883 | N254: 199445.54 | O254: 7793.4539 | P254: 207238.99 | Q254: ND | R254: ND | T254: 131829.51 | U254: 3599.473 | V254: 135428.98 | W254: 8130.2442 | X254: 0.11169123 | Y254: 8130.3559 | Z254: 139959.75 | AA254: 3599.5847 | AB254: 143559.34 | AC254: ND | AD254: 1799.4258 | AE254: 128.19794 | AF254: 1927.6238 | AG254: 20.766832 | AH254: 0.0009611 | AI254: 20.767793 | AJ254: 1820.1926 | AK254: 128.1989 | AL254: 1948.3915 | AM254: ND
A255: 43525 | B255: 193152.77 | C255: 8014.8712 | D255: 201167.65 | E255: 8688.8528 | F255: 0.13731052 | G255: 8688.9901 | H255: 201841.63 | I255: 8015.0085 | J255: 209856.64 | K255: 52.159494 | L255: 7.863767 | M255: 60.023261 | N255: 201893.79 | O255: 8022.8723 | P255: 209916.66 | Q255: ND | R255: ND | T255: 133225.97 | U255: 3683.9249 | V255: 136909.89 | W255: 8003.8132 | X255: 0.10125696 | Y255: 8003.9145 | Z255: 141229.78 | AA255: 3684.0261 | AB255: 144913.81 | AC255: ND | AD255: 1789.7146 | AE255: 129.34376 | AF255: 1919.0584 | AG255: 20.458713 | AH255: 0.00107674 | AI255: 20.45979 | AJ255: 1810.1734 | AK255: 129.34483 | AL255: 1939.5182 | AM255: ND
A256: 43556 | B256: 195259.9 | C256: 8882.0222 | D256: 204141.92 | E256: 9719.9377 | F256: 0.14344939 | G256: 9720.0812 | H256: 204979.83 | I256: 8882.1656 | J256: 213862 | K256: 53.524852 | L256: 8.2639198 | M256: 61.788772 | N256: 205033.36 | O256: 8890.4295 | P256: 213923.79 | Q256: ND | R256: ND | T256: 133259.55 | U256: 3778.6416 | V256: 137038.19 | W256: 9008.8359 | X256: 0 | Y256: 9008.8359 | Z256: 142268.38 | AA256: 3778.6416 | AB256: 146047.02 | AC256: ND | AD256: 1772.4007 | AE256: 145.89007 | AF256: 1918.2908 | AG256: 20.32823 | AH256: 0.0012813 | AI256: 20.329512 | AJ256: 1792.729 | AK256: 145.89135 | AL256: 1938.6203 | AM256: ND
A257: 43586 | B257: 195162.23 | C257: 8942.8183 | D257: 204105.05 | E257: 9248.1724 | F257: 0.1445607 | G257: 9248.317 | H257: 204410.4 | I257: 8942.9629 | J257: 213353.36 | K257: 52.595254 | L257: 8.5547981 | M257: 61.150052 | N257: 204463 | O257: 8951.5177 | P257: 213414.51 | Q257: ND | R257: ND | T257: 133294.42 | U257: 3652.0857 | V257: 136946.51 | W257: 8557.5879 | X257: 0.10702331 | Y257: 8557.6949 | Z257: 141852.01 | AA257: 3652.1928 | AB257: 145504.2 | AC257: ND | AD257: 1755.0156 | AE257: 150.08319 | AF257: 1905.0988 | AG257: 19.589938 | AH257: 0.00059837 | AI257: 19.590536 | AJ257: 1774.6055 | AK257: 150.08379 | AL257: 1924.6893 | AM257: ND
A258: 43617 | B258: 195025.58 | C258: 8050.9528 | D258: 203076.54 | E258: 9948.1907 | F258: 0.14427364 | G258: 9948.335 | H258: 204973.77 | I258: 8051.097 | J258: 213024.87 | K258: 55.835895 | L258: 8.3219369 | M258: 64.157832 | N258: 205029.61 | O258: 8059.419 | P258: 213089.03 | Q258: ND | R258: ND | T258: 133484.44 | U258: 3651.4788 | V258: 137135.92 | W258: 9264.2585 | X258: 0 | Y258: 9264.2585 | Z258: 142748.7 | AA258: 3651.4788 | AB258: 146400.18 | AC258: ND | AD258: 1749.2225 | AE258: 125.049 | AF258: 1874.2715 | AG258: 19.439834 | AH258: 0.00093726 | AI258: 19.440771 | AJ258: 1768.6623 | AK258: 125.04994 | AL258: 1893.7122 | AM258: ND
A259: 43647 | B259: 192628.72 | C259: 7833.6887 | D259: 200462.4 | E259: 9222.5861 | F259: 0.072774253 | G259: 9222.6588 | H259: 201851.3 | I259: 7833.7615 | J259: 209685.06 | K259: 63.323075 | L259: 7.1585022 | M259: 70.481578 | N259: 201914.62 | O259: 7840.92 | P259: 209755.54 | Q259: ND | R259: ND | T259: 133707.35 | U259: 3588.5281 | V259: 137295.88 | W259: 8563.9962 | X259: 0.067070092 | Y259: 8564.0633 | Z259: 142271.35 | AA259: 3588.5281 | AB259: 145859.88 | AC259: ND | AD259: 1715.3235 | AE259: 123.58546 | AF259: 1838.909 | AG259: 19.172921 | AH259: 0.00016606 | AI259: 19.173087 | AJ259: 1734.4965 | AK259: 123.58563 | AL259: 1858.0821 | AM259: ND
A260: 43678 | B260: 194779.76 | C260: 9602.7968 | D260: 204382.56 | E260: 9712.7088 | F260: 0.059696414 | G260: 9712.7684 | H260: 204492.47 | I260: 9602.8565 | J260: 214095.32 | K260: 47.204002 | L260: 5.9929486 | M260: 53.19695 | N260: 204539.67 | O260: 9608.8495 | P260: 214148.52 | Q260: ND | R260: ND | T260: 134145.59 | U260: 3753.9276 | V260: 137899.51 | W260: 9049.7669 | X260: 0.051561523 | Y260: 9049.8184 | Z260: 143195.35 | AA260: 3753.9792 | AB260: 146949.33 | AC260: ND | AD260: 1654.7725 | AE260: 159.622 | AF260: 1814.3945 | AG260: 18.092404 | AH260: 0.00022201 | AI260: 18.092626 | AJ260: 1672.8649 | AK260: 159.62222 | AL260: 1832.4871 | AM260: ND
A261: 43709 | B261: 194922.5 | C261: 9463.3848 | D261: 204385.89 | E261: 9761.6186 | F261: 0.077743297 | G261: 9761.6964 | H261: 204684.12 | I261: 9463.4625 | J261: 214147.58 | K261: 50.453473 | L261: 5.6970828 | M261: 56.150556 | N261: 204734.57 | O261: 9469.1596 | P261: 214203.73 | Q261: ND | R261: ND | T261: 134791.5 | U261: 3921.9241 | V261: 138713.43 | W261: 9125.9696 | X261: 0.065367624 | Y261: 9126.035 | Z261: 143917.47 | AA261: 3921.9895 | AB261: 147839.46 | AC261: ND | AD261: 1627.8459 | AE261: 150.01653 | AF261: 1777.8625 | AG261: 17.208074 | AH261: 0.00033503 | AI261: 17.208409 | AJ261: 1645.054 | AK261: 150.01687 | AL261: 1795.0709 | AM261: ND
A262: 43739 | B262: 198754.24 | C262: 8495.262 | D262: 207249.5 | E262: 11210.888 | F262: 0.032919719 | G262: 11210.921 | H262: 209965.12 | I262: 8495.2949 | J262: 218460.42 | K262: 54.029595 | L262: 5.7625807 | M262: 59.792176 | N262: 210019.15 | O262: 8501.0575 | P262: 218520.21 | Q262: ND | R262: ND | T262: 137321.77 | U262: 3925.495 | V262: 141247.27 | W262: 10565.068 | X262: 0.016132283 | Y262: 10565.084 | Z262: 147886.84 | AA262: 3925.5111 | AB262: 151812.35 | AC262: ND | AD262: 1641.8768 | AE262: 122.13403 | AF262: 1764.0109 | AG262: 17.26052 | AH262: 0.00044867 | AI262: 17.260968 | AJ262: 1659.1374 | AK262: 122.13448 | AL262: 1781.2718 | AM262: ND
A263: 43770 | B263: 200250.03 | C263: 8613.8961 | D263: 208863.92 | E263: 10060.917 | F263: 0.022498529 | G263: 10060.94 | H263: 210310.95 | I263: 8613.9185 | J263: 218924.86 | K263: 54.089274 | L263: 5.6676498 | M263: 59.756924 | N263: 210365.03 | O263: 8619.5862 | P263: 218984.62 | Q263: ND | R263: ND | T263: 138510.81 | U263: 3902.7551 | V263: 142413.56 | W263: 9448.1309 | X263: 0.0076818984 | Y263: 9448.1386 | Z263: 147958.94 | AA263: 3902.7627 | AB263: 151861.7 | AC263: ND | AD263: 1631.5862 | AE263: 124.50161 | AF263: 1756.0878 | AG263: 16.194148 | AH263: 0.00039156 | AI263: 16.194539 | AJ263: 1647.7803 | AK263: 124.502 | AL263: 1772.2823 | AM263: ND
A264: 43800 | B264: 204187.11 | C264: 8492.0565 | D264: 212679.17 | E264: 10122.723 | F264: 0.010717672 | G264: 10122.734 | H264: 214309.83 | I264: 8492.0672 | J264: 222801.9 | K264: 52.544677 | L264: 11.648739 | M264: 64.193416 | N264: 214362.38 | O264: 8503.716 | P264: 222866.09 | Q264: ND | R264: ND | T264: 143632.86 | U264: 3720.5109 | V264: 147353.37 | W264: 9514.269 | X264: 0.010717672 | Y264: 9514.2797 | Z264: 153147.13 | AA264: 3720.5216 | AB264: 156867.65 | AC264: ND | AD264: 1621.8729 | AE264: 127.80013 | AF264: 1749.673 | AG264: 16.296714 | AH264: 0 | AI264: 16.296714 | AJ264: 1638.1696 | AK264: 127.80013 | AL264: 1765.9697 | AM264: ND
... A324: 45627 | B324: 331305.27 | C324: 7890.157 | D324: 339195.43 | E324: 22032.701 | F324: 0.0027563283 | G324: 22032.704 | H324: 353337.97 | I324: 7890.1598 | J324: 361228.13 | K324: 84.412889 | L324: 3.712122 | M324: 88.125011 | N324: 353422.38 | O324: 7893.8719 | P324: 361316.26 | Q324: ND | R324: ND | T324: 212159.5 | U324: 5439.9399 | V324: 217599.44 | W324: 17095.037 | X324: 0 | Y324: 17095.037 | Z324: 229254.54 | AA324: 5439.9399 | AB324: 234694.48 | AC324: ND | AD324: 2703.8028 | AE324: 55.603348 | AF324: 2759.4061 | AG324: 112.05155 | AH324: 6.255e-05 | AI324: 112.05162 | AJ324: 2815.8543 | AK324: 55.603411 | AL324: 2871.4577 | AM324: ND
A325: 45658 | B325: =+'[1]Bcos. Públ.'!B325*[2]TC!$B316 -> 329482.3 | C325: =+'[1]Bcos. Públ.'!C325*[2]TC!$B316 -> 7593.5694 | D325: =+'[1]Bcos. Públ.'!D325*[2]TC!$B316 -> 337075.87 | E325: =+'[1]Bcos. Públ.'!E325*[2]TC!$B316 -> 22681.986 | F325: =+'[1]Bcos. Públ.'!F325*[2]TC!$B316 -> 0.0098326784 | G325: =+'[1]Bcos. Públ.'!G325*[2]TC!$B316 -> 22681.996 | H325: =+'[1]Bcos. Públ.'!H325*[2]TC!$B316 -> 352164.28 | I325: =+'[1]Bcos. Públ.'!I325*[2]TC!$B316 -> 7593.5792 | ... P325: =+'[1]Bcos. Públ.'!P325*[2]TC!$B316 -> 359835.59 | Q325: ND | R325: ND | T325: =+'[1]Bcos. Públ.'!T325*[2]TC!$B316 -> 213846.29 | U325: =+'[1]Bcos. Públ.'!U325*[2]TC!$B316 -> 5212.6751 | V325: =+'[1]Bcos. Públ.'!V325*[2]TC!$B316 -> 219058.96 | W325: =+'[1]Bcos. Públ.'!W325*[2]TC!$B316 -> 21197.089 | X325: =+'[1]Bcos. Públ.'!X325*[2]TC!$B316 -> 0.0062263856 | Y325: =+'[1]Bcos. Públ.'!Y325*[2]TC!$B316 -> 21197.095 | Z325: =+'[1]Bcos. Públ.'!Z325*[2]TC!$B316 -> 235043.37 | AA325: =+'[1]Bcos. Públ.'!AA325*[2]TC!$B316 -> 5212.6813 | AB325: =+'[1]Bcos. Públ.'!AB325*[2]TC!$B316 -> 240256.06 | AC325: ND | AD325: =+'[1]Bcos. Públ.'!AD325 -> 2681.6013 | AE325: =+'[1]Bcos. Públ.'!AE325 -> 55.212984 | AF325: =+'[1]Bcos. Públ.'!AF325 -> 2736.8143 | AG325: =+'[1]Bcos. Públ.'!AG325 -> 34.434803 | AH325: =+'[1]Bcos. Públ.'!AH325 -> 8.363e-05 | AI325: =+'[1]Bcos. Públ.'!AI325 -> 34.434887 | AJ325: =+'[1]Bcos. Públ.'!AJ325 -> 2716.0361 | AK325: =+'[1]Bcos. Públ.'!AK325 -> 55.213068 | AL325: =+'[1]Bcos. Públ.'!AL325 -> 2771.2492 | AM325: ND
A326: 45689 | B326: =+'[1]Bcos. Públ.'!B326*[2]TC!$B317 -> 331475.31 | C326: =+'[1]Bcos. Públ.'!C326*[2]TC!$B317 -> 7827.7992 | D326: =+'[1]Bcos. Públ.'!D326*[2]TC!$B317 -> 339303.11 | E326: =+'[1]Bcos. Públ.'!E326*[2]TC!$B317 -> 22192.774 | F326: =+'[1]Bcos. Públ.'!F326*[2]TC!$B317 -> 0 | G326: =+'[1]Bcos. Públ.'!G326*[2]TC!$B317 -> 22192.774 | H326: =+'[1]Bcos. Públ.'!H326*[2]TC!$B317 -> 353668.08 | I326: =+'[1]Bcos. Públ.'!I326*[2]TC!$B317 -> 7827.7992 | ... P326: =+'[1]Bcos. Públ.'!P326*[2]TC!$B317 -> 361574.66 | Q326: ND | R326: ND | T326: =+'[1]Bcos. Públ.'!T326*[2]TC!$B317 -> 215922.09 | U326: =+'[1]Bcos. Públ.'!U326*[2]TC!$B317 -> 5413.14 | V326: =+'[1]Bcos. Públ.'!V326*[2]TC!$B317 -> 221335.23 | W326: =+'[1]Bcos. Públ.'!W326*[2]TC!$B317 -> 20723.066 | X326: =+'[1]Bcos. Públ.'!X326*[2]TC!$B317 -> 0 | Y326: =+'[1]Bcos. Públ.'!Y326*[2]TC!$B317 -> 20723.066 | Z326: =+'[1]Bcos. Públ.'!Z326*[2]TC!$B317 -> 236645.16 | AA326: =+'[1]Bcos. Públ.'!AA326*[2]TC!$B317 -> 5413.14 | AB326: =+'[1]Bcos. Públ.'!AB326*[2]TC!$B317 -> 242058.3 | AC326: ND | AD326: =+'[1]Bcos. Públ.'!AD326 -> 2713.4723 | AE326: =+'[1]Bcos. Públ.'!AE326 -> 56.702105 | AF326: =+'[1]Bcos. Públ.'!AF326 -> 2770.1744 | AG326: =+'[1]Bcos. Públ.'!AG326 -> 34.51233 | AH326: =+'[1]Bcos. Públ.'!AH326 -> 0 | AI326: =+'[1]Bcos. Públ.'!AI326 -> 34.51233 | AJ326: =+'[1]Bcos. Públ.'!AJ326 -> 2747.9846 | AK326: =+'[1]Bcos. Públ.'!AK326 -> 56.702105 | AL326: =+'[1]Bcos. Públ.'!AL326 -> 2804.6867 | AM326: ND
A327: 45717 | B327: =+'[1]Bcos. Públ.'!B327*[2]TC!$B318 -> 334965.14 | C327: =+'[1]Bcos. Públ.'!C327*[2]TC!$B318 -> 7533.0612 | D327: =+'[1]Bcos. Públ.'!D327*[2]TC!$B318 -> 342498.2 | E327: =+'[1]Bcos. Públ.'!E327*[2]TC!$B318 -> 22377.421 | F327: =+'[1]Bcos. Públ.'!F327*[2]TC!$B318 -> 0.013159632 | G327: =+'[1]Bcos. Públ.'!G327*[2]TC!$B318 -> 22377.434 | H327: =+'[1]Bcos. Públ.'!H327*[2]TC!$B318 -> 357342.56 | I327: =+'[1]Bcos. Públ.'!I327*[2]TC!$B318 -> 7533.0744 | ... P327: =+'[1]Bcos. Públ.'!P327*[2]TC!$B318 -> 364950.66 | Q327: ND | R327: ND | T327: =+'[1]Bcos. Públ.'!T327*[2]TC!$B318 -> 217630.88 | U327: =+'[1]Bcos. Públ.'!U327*[2]TC!$B318 -> 5251.3194 | V327: =+'[1]Bcos. Públ.'!V327*[2]TC!$B318 -> 222882.2 | W327: =+'[1]Bcos. Públ.'!W327*[2]TC!$B318 -> 20912.912 | X327: =+'[1]Bcos. Públ.'!X327*[2]TC!$B318 -> 0 | Y327: =+'[1]Bcos. Públ.'!Y327*[2]TC!$B318 -> 20912.912 | Z327: =+'[1]Bcos. Públ.'!Z327*[2]TC!$B318 -> 238543.8 | AA327: =+'[1]Bcos. Públ.'!AA327*[2]TC!$B318 -> 5251.3194 | AB327: =+'[1]Bcos. Públ.'!AB327*[2]TC!$B318 -> 243795.12 | AC327: ND | AD327: =+'[1]Bcos. Públ.'!AD327 -> 2785.2507 | AE327: =+'[1]Bcos. Públ.'!AE327 -> 54.163407 | AF327: =+'[1]Bcos. Públ.'!AF327 -> 2839.4141 | AG327: =+'[1]Bcos. Públ.'!AG327 -> 34.764133 | AH327: =+'[1]Bcos. Públ.'!AH327 -> 0.00031238 | AI327: =+'[1]Bcos. Públ.'!AI327 -> 34.764445 | AJ327: =+'[1]Bcos. Públ.'!AJ327 -> 2820.0149 | AK327: =+'[1]Bcos. Públ.'!AK327 -> 54.163719 | AL327: =+'[1]Bcos. Públ.'!AL327 -> 2874.1786 | AM327: ND
...

Sheet Bcos. Priv.
A1: Banco Central del Uruguay | T1: Banco Central del Uruguay
A2: Superintendencia de Servicios Financieros | T2: Superintendencia de Instituciones de Intermediación Financiera
M3: Volver al Índice | AH3: Volver al Índice
B4: CRÉDITOS BRUTOS SECTOR NO FINANCIERO (SNF) (1) | T4: CRÉDITOS BRUTOS SNF (1) - ANEXO RESIDENTES POR MONEDAS
B5: BANCOS PRIVADOS (2) | T5: BANCOS PRIVADOS (2)
B6: (Crédito Total en millones de pesos) | T6: (Créditos en MN en millones de pesos y en ME en millones de dólares)
B8: TOTAL (MN + ME) en millones de pesos
B9: RESIDENTES | K9: NO RESIDENTES (5) | N9: TOTAL | Q9: Variación mensual | T9: MONEDA NACIONAL en millones de pesos | AD9: MONEDA EXTRANJERA en millones de dólares
A10: Mes | B10: SECTOR PRIVADO (3) | E10: SECTOR PÚBLICO (4) | H10: TOTAL (S.Priv. + S.Públ) | Q10: Castigados (1) | T10: SECTOR PRIVADO (3) | W10: SECTOR PÚBLICO (4) | Z10: TOTAL (S.Priv. + S.Públ) | AC10: Variac. mens. | AD10: SECTOR PRIVADO (3) | AG10: SECTOR PÚBLICO (4) | AJ10: TOTAL (S.Priv. + S.Públ) | AM10: Variac. mens.
B11: Vigentes | C11: Vencidos | D11: Total | E11: Vigentes | F11: Vencidos | G11: Total | H11: Vigentes | I11: Vencidos | J11: Total | K11: Vigentes | L11: Vencidos | M11: Total | N11: Vigentes | O11: Vencidos | P11: Total | Q11: Resid. | R11: No resid. | T11: Vigentes | U11: Vencidos | V11: Total | W11: Vigentes | X11: Vencidos | Y11: Total | Z11: Vigentes | AA11: Vencidos | AB11: Total | AC11: Castigados (1) | AD11: Vigentes | AE11: Vencidos | AF11: Total | AG11: Vigentes | AH11: Vencidos | AI11: Total | AJ11: Vigentes | AK11: Vencidos | AL11: Total | AM11: Castigados (1)
A12: 36161 | B12: 41389.81 | C12: 4223.45 | D12: 45613.26 | E12: 537.53 | F12: 0 | G12: 537.53 | H12: 41927.34 | I12: 4223.45 | J12: 46150.79 | K12: 9258.68 | L12: 197.46 | M12: 9456.14 | N12: 51186.02 | O12: 4409.94 | P12: 55606.93 | Q12: 68.74794 | R12: 79.222487 | T12: 7251.17 | U12: 998.27 | V12: 8260.41 | W12: 43.88 | X12: 0 | Y12: 43.88 | Z12: 7295.05 | AA12: 998.27 | AB12: 8304.29 | AC12: 1.1683086 | AD12: 3112 | AE12: 294 | AF12: 3405 | AG12: 45 | AH12: 0 | AI12: 45 | AJ12: 3157 | AK12: 294 | AL12: 3451 | AM12: 6.1604039 | AN12: =+AE12/AF12 -> 0.086343612 | AO12: =+U12/V12 -> 0.12084993
A13: 36192 | B13: 40875.185 | C13: 4745.52 | D13: 45620.705 | E13: 450.385 | F13: 0 | G13: 450.385 | H13: 41325.57 | I13: 4745.52 | J13: 46071.09 | K13: 9370.205 | L13: 164.775 | M13: 9534.98 | N13: 50695.775 | O13: 4921.28 | P13: 55617.055 | Q13: 177.05241 | R13: 20.485804 | T13: 6953.505 | U13: 1208.35 | V13: 8172.84 | W13: 32.955 | X13: 0 | Y13: 32.955 | Z13: 6986.46 | AA13: 1219.335 | AB13: 8205.795 | AC13: 3.5704229 | AD13: 3088 | AE13: 322 | AF13: 3409 | AG13: 38 | AH13: 0 | AI13: 38 | AJ13: 3126 | AK13: 322 | AL13: 3447 | AM13: 15.792625 | AN13: =+AE13/AF13 -> 0.094455852 | AO13: =+U13/V13 -> 0.14784946
A14: 36220 | B14: 41106.975 | C14: 3261.93 | D14: 44357.81 | E14: 432.705 | F14: 0 | G14: 432.705 | H14: 41539.68 | I14: 3261.93 | J14: 44801.61 | K14: 9852.36 | L14: 99.855 | M14: 9952.215 | N14: 51392.04 | O14: 3361.785 | P14: 54753.825 | Q14: 1316.3836 | R14: -2.7443804 | T14: 6812.33 | U14: 920.885 | V14: 7733.215 | W14: 33.285 | X14: 0 | Y14: 33.285 | Z14: 6856.71 | AA14: 920.885 | AB14: 7766.5 | AC14: 188.58675 | AD14: 3090 | AE14: 211 | AF14: 3301 | AG14: 36 | AH14: 0 | AI14: 36 | AJ14: 3126 | AK14: 211 | AL14: 3337 | AM14: 101.64911 | AN14: =+AE14/AF14 -> 0.063920024 | AO14: =+U14/V14 -> 0.11908178
A15: 36251 | B15: 40827.952 | C15: 2997.467 | D15: 43825.419 | E15: 445.72 | F15: 0 | G15: 445.72 | H15: 41273.672 | I15: 2997.467 | J15: 44271.139 | K15: 9995.271 | L15: 89.144 | M15: 10084.415 | N15: 51268.943 | O15: 3086.611 | P15: 54366.697 | Q15: 504.03413 | R15: 0.33674713 | T15: 6663.514 | U15: 735.438 | V15: 7398.952 | W15: 44.572 | X15: 0 | Y15: 44.572 | Z15: 6708.086 | AA15: 735.438 | AB15: 7432.381 | AC15: 202.23106 | AD15: 3066 | AE15: 203 | AF15: 3269 | AG15: 37 | AH15: 0 | AI15: 37 | AJ15: 3102 | AK15: 203 | AL15: 3306 | AM15: 27.084544 | AN15: =+AE15/AF15 -> 0.062098501 | AO15: =+U15/V15 -> 0.09939759
A16: 36281 | B16: 41179.047 | C16: 3167.619 | D16: 44335.473 | E16: 514.878 | F16: 0 | G16: 526.071 | H16: 41693.925 | I16: 3167.619 | J16: 44861.544 | K16: 10174.437 | L16: 100.737 | M16: 10275.174 | N16: 51868.362 | O16: 3268.356 | P16: 55136.718 | Q16: 43.680147 | R16: 16.727124 | T16: 6771.765 | U16: 749.931 | V16: 7532.889 | W16: 55.965 | X16: 0 | Y16: 55.965 | Z16: 6827.73 | AA16: 749.931 | AB16: 7577.661 | AC16: 5.056745 | AD16: 3073 | AE16: 215 | AF16: 3289 | AG16: 42 | AH16: 0 | AI16: 42 | AJ16: 3115 | AK16: 215 | AL16: 3331 | AM16: 3.4506747 | AN16: =+AE16/AF16 -> 0.065369413 | AO16: =+U16/V16 -> 0.099554235
A17: 36312 | B17: 42106.813 | C17: 3127.025 | D17: 45233.838 | E17: 477.582 | F17: 0 | G17: 477.582 | H17: 42584.395 | I17: 3127.025 | J17: 45711.42 | K17: 9995.109 | L17: 79.597 | M17: 10074.706 | N17: 52579.504 | O17: 3206.622 | P17: 55786.126 | Q17: 26.529893 | R17: 3.2587873 | T17: 6845.342 | U17: 750.486 | V17: 7595.828 | W17: 68.226 | X17: 0 | Y17: 68.226 | Z17: 6913.568 | AA17: 750.486 | AB17: 7664.054 | AC17: 1.7881484 | AD17: 3101 | AE17: 209 | AF17: 3310 | AG17: 36 | AH17: 0 | AI17: 36 | AJ17: 3137 | AK17: 209 | AL17: 3346 | AM17: 2.1758636 | AN17: =+AE17/AF17 -> 0.063141994 | AO17: =+U17/V17 -> 0.098802395
A18: 36342 | B18: 42423.5 | C18: 3231.5 | D18: 45666.5 | E18: 460 | F18: 0 | G18: 460 | H18: 42883.5 | I18: 3243 | J18: 46126.5 | K18: 9970.5 | L18: 103.5 | M18: 10074 | N18: 52854 | O18: 3335 | P18: 56200.5 | Q18: 9.0791451 | R18: -2.3147588 | T18: 7003.5 | U18: 793.5 | V18: 7797 | W18: 69 | X18: 0 | Y18: 69 | Z18: 7072.5 | AA18: 793.5 | AB18: 7877.5 | AC18: 10.073454 | AD18: 3080 | AE18: 212 | AF18: 3292 | AG18: 34 | AH18: 0 | AI18: 34 | AJ18: 3114 | AK18: 212 | AL18: 3326 | AM18: -0.086461607 | AN18: =+AE18/AF18 -> 0.064398542 | AO18: =+U18/V18 -> 0.10176991
A19: 36373 | B19: 43102.175 | C19: 3441.175 | D19: 46543.35 | E19: 571.585 | F19: 0 | G19: 571.585 | H19: 43673.76 | I19: 3441.175 | J19: 47126.6 | K19: 10090.225 | L19: 104.985 | M19: 10195.21 | N19: 53763.985 | O19: 3557.825 | P19: 57321.81 | Q19: 28.656016 | R19: -6.4389659 | T19: 7337.285 | U19: 793.22 | V19: 8130.505 | W19: 69.99 | X19: 0 | Y19: 69.99 | Z19: 7407.275 | AA19: 793.22 | AB19: 8200.495 | AC19: 10.225124 | AD19: 3066 | AE19: 227 | AF19: 3293 | AG19: 43 | AH19: 0 | AI19: 43 | AJ19: 3109 | AK19: 227 | AL19: 3336 | AM19: 1.5800165 | AN19: =+AE19/AF19 -> 0.068934103 | AO19: =+U19/V19 -> 0.097560976
A20: 36404 | B20: 43258.6 | C20: 3591.28 | D20: 46849.88 | E20: 617.98 | F20: 0 | G20: 629.64 | H20: 43888.24 | I20: 3602.94 | J20: 47479.52 | K20: 9969.3 | L20: 116.6 | M20: 10085.9 | N20: 53845.88 | O20: 3707.88 | P20: 57565.42 | Q20: 35.330026 | R20: 0.51881683 | T20: 7474.06 | U20: 851.18 | V20: 8325.24 | W20: 93.28 | X20: 0 | Y20: 104.94 | Z20: 7567.34 | AA20: 851.18 | AB20: 8430.18 | AC20: 9.9414587 | AD20: 3069 | AE20: 235 | AF20: 3304 | AG20: 45 | AH20: 0 | AI20: 45 | AJ20: 3114 | AK20: 235 | AL20: 3350 | AM20: 2.1774071 | AN20: =+AE20/AF20 -> 0.071125908 | AO20: =+U20/V20 -> 0.1022409
A21: 36434 | B21: 43260.23 | C21: 3737.11 | D21: 47008.91 | E21: 647.92 | F21: 0 | G21: 659.49 | H21: 43919.72 | I21: 3748.68 | J21: 47668.4 | K21: 9811.36 | L21: 115.7 | M21: 9927.06 | N21: 53731.08 | O21: 3864.38 | P21: 57595.46 | Q21: 35.678785 | R21: 0.36730447 | T21: 7462.65 | U21: 890.89 | V21: 8353.54 | W21: 80.99 | X21: 0 | Y21: 92.56 | Z21: 7543.64 | AA21: 902.46 | AB21: 8446.1 | AC21: 11.419696 | AD21: 3095 | AE21: 246 | AF21: 3341 | AG21: 49 | AH21: 0 | AI21: 49 | AJ21: 3144 | AK21: 246 | AL21: 3390 | AM21: 2.0967233 | AN21: =+AE21/AF21 -> 0.07363065 | AO21: =+U21/V21 -> 0.1066482
A22: 36465 | B22: 43216.358 | C22: 3880.464 | D22: 47085.273 | E22: 692.94 | F22: 0 | G22: 692.94 | H22: 43909.298 | I22: 3880.464 | J22: 47789.762 | K22: 14863.563 | L22: 334.921 | M22: 15210.033 | N22: 58772.861 | O22: 4215.385 | P22: 62999.795 | Q22: 30.14972 | R22: 39.245595 | T22: 7345.164 | U22: 923.92 | V22: 8280.633 | W22: 80.843 | X22: 0 | Y22: 92.392 | Z22: 7437.556 | AA22: 935.469 | AB22: 8361.476 | AC22: 7.9688927 | AD22: 3105 | AE22: 255 | AF22: 3361 | AG22: 53 | AH22: 0 | AI22: 53 | AJ22: 3158 | AK22: 255 | AL22: 3413 | AM22: 1.9205843 | AN22: =+AE22/AF22 -> 0.075870277 | AO22: =+U22/V22 -> 0.11157601
A23: 36495 | B23: 44334.455 | C23: 3867.795 | D23: 48202.25 | E23: 662.055 | F23: 0 | G23: 673.67 | H23: 45008.125 | I23: 3867.795 | J23: 48875.92 | K23: 15447.95 | L23: 336.835 | M23: 15784.785 | N23: 60456.075 | O23: 4204.63 | P23: 64660.705 | Q23: 6.7811529 | R23: 0.02820553 | T23: 7468.445 | U23: 940.815 | V23: 8409.26 | W23: 81.305 | X23: 0 | Y23: 81.305 | Z23: 7549.75 | AA23: 940.815 | AB23: 8490.565 | AC23: -41.852945 | AD23: 3174 | AE23: 252 | AF23: 3426 | AG23: 51 | AH23: 0 | AI23: 51 | AJ23: 3225 | AK23: 252 | AL23: 3477 | AM23: 4.1871802 | AN23: =+AE23/AF23 -> 0.073555166 | AO23: =+U23/V23 -> 0.11187845
... A52: 37377 | B52: 52560.04 | C52: 10571.66 | D52: 63131.7 | E52: 2303.23 | F52: 115.99 | G52: 2419.22 | H52: 54863.27 | I52: 10671.08 | J52: 65550.92 | K52: 14382.76 | L52: 2170.67 | M52: 16553.43 | N52: 69246.03 | O52: 12841.75 | P52: 82087.78 | Q52: 121.49717 | R52: 0.21577984 | T52: 6263.46 | U52: 1093.62 | V52: 7357.08 | W52: 314.83 | X52: 16.57 | Y52: 331.4 | Z52: 6578.29 | AA52: 1110.19 | AB52: 7688.48 | AC52: 23.014741 | AD52: 2794 | AE52: 571 | AF52: 3365 | AG52: 120 | AH52: 6 | AI52: 126 | AJ52: 2914 | AK52: 577 | AL52: 3491 | AM52: 5.9434173 | AN52: =+AE52/AF52 -> 0.16968796 | AO52: =+U52/V52 -> 0.14864865
A53: 37408 | B53: 54575 | C53: 12617 | D53: 67192 | E53: 2534.5 | F53: 92.5 | G53: 2627 | H53: 57109.5 | I53: 12728 | J53: 69819 | K53: 14559.5 | L53: 3034 | M53: 17593.5 | N53: 71650.5 | O53: 15762 | P53: 87412.5 | Q53: 238.75751 | R53: 6.206763 | T53: 5957 | U53: 1147 | V53: 7104 | W53: 296 | X53: 18.5 | Y53: 296 | Z53: 6234.5 | AA53: 1165.5 | AB53: 7400 | AC53: 19.224503 | AD53: 2628 | AE53: 621 | AF53: =+AD53+AE53 -> 3249 | AG53: 121 | AH53: 4 | AI53: 125 | AJ53: 2749 | AK53: 625 | AL53: 3374 | AM53: 11.866649 | AN53: =+AE53/AF53 -> 0.19113573 | AO53: =+U53/V53 -> 0.16145833
A54: 37438 | B54: 67225 | C54: 18700 | D54: 85925 | E54: 3175 | F54: 125 | G54: 3300 | H54: 70375 | I54: 18825 | J54: 89200 | K54: 18975 | L54: 5175 | M54: 24125 | N54: 89350 | O54: 24000 | P54: 113350 | Q54: 170.03853 | R54: 6.9581322 | T54: 5650 | U54: 1250 | V54: 6900 | W54: 300 | X54: 25 | Y54: 325 | Z54: 5950 | AA54: 1250 | AB54: 7200 | AC54: 41.321322 | AD54: 2463 | AE54: 698 | AF54: =+AD54+AE54 -> 3161 | AG54: 115 | AH54: 4 | AI54: 119 | AJ54: 2577 | AK54: 703 | AL54: 3280 | AM54: 5.1486883 | AN54: =+AE54/AF54 -> 0.2208162 | AO54: =+U54/V54 -> 0.18115942
A55: 37469 | B55: 69235.2 | C55: 25776 | D55: 95040 | E55: 3542.4 | F55: 172.8 | G55: 3715.2 | H55: 72777.6 | I55: 25948.8 | J55: 98726.4 | K55: 11980.8 | L55: 7891.2 | M55: 19843.2 | N55: 84758.4 | O55: 33840 | P55: 118598.4 | Q55: 239.69773 | R55: 3.5423197 | T55: 5356.8 | U55: 1411.2 | V55: 6768 | W55: 288 | X55: 28.8 | Y55: 288 | Z55: 5616 | AA55: 1440 | AB55: 7056 | AC55: 13.440429 | AD55: =+AD54+($AD$54-$AD$71)/17 -> 2540.2941 | AE55: 846 | AF55: =+AD55+AE55 -> 3386.2941 | AG55: 113 | AH55: 6 | AI55: 118 | AJ55: 2331 | AK55: 852 | AL55: 3183 | AM55: 7.8561564 | AN55: =+AE55/AF55 -> 0.24983063 | AO55: =+U55/V55 -> 0.20851064
A56: 37500 | B56: 57267 | C56: 28134 | D56: 85428 | E56: 3348 | F56: 135 | G56: 3483 | H56: 60615 | I56: 28296 | J56: 88911 | K56: 9234 | L56: 7182 | M56: 16443 | N56: 69876 | O56: 35478 | P56: 105354 | Q56: 446.09183 | R56: 7.9424823 | T56: 4806 | U56: 1674 | V56: 6480 | W56: 270 | X56: 27 | Y56: 297 | Z56: 5076 | AA56: 1701 | AB56: 6777 | AC56: 42.684801 | AD56: =+AD55+($AD$54-$AD$71)/17 -> 2617.5882 | AE56: 980 | AF56: =+AD56+AE56 -> 3597.5882 | AG56: 114 | AH56: 5 | AI56: 118 | AJ56: 2057 | AK56: 985 | AL56: 3042 | AM56: 14.941001 | AN56: =+AE56/AF56 -> 0.27240472 | AO56: =+U56/V56 -> 0.25833333
A57: 37530 | B57: 51584.35 | C57: 30809.95 | D57: 82394.3 | E57: 3300.1 | F57: 135.25 | G57: 3435.35 | H57: 54884.45 | I57: 30945.2 | J57: 85829.65 | K57: 7492.85 | L57: 7601.05 | M57: 15093.9 | N57: 62404.35 | O57: 38546.25 | P57: 100923.55 | Q57: 200.86621 | R57: 1.9425339 | T57: 4409.15 | U57: 1785.3 | V57: 6194.45 | W57: 270.5 | X57: 0 | Y57: 297.55 | Z57: 4706.7 | AA57: 1812.35 | AB57: 6492 | AC57: 31.656531 | AD57: =+AD56+($AD$54-$AD$71)/17 -> 2694.8824 | AE57: 1073 | AF57: =+AD57+AE57 -> 3767.8824 | AG57: 112 | AH57: 5 | AI57: 117 | AJ57: 1856 | AK57: 1078 | AL57: 2933 | AM57: 6.2554408 | AN57: =+AE57/AF57 -> 0.28477535 | AO57: =+U57/V57 -> 0.28820961
A58: 37561 | B58: 45948 | C58: 33202.9 | D58: 79123.55 | E58: 3008.5 | F58: 300.85 | G58: 3309.35 | H58: 48929.15 | I58: 33503.75 | J58: 82432.9 | K58: 6864.85 | L58: 7712.7 | M58: 14577.55 | N58: 55794 | O58: 41216.45 | P58: 97010.45 | Q58: 479.91615 | R58: 141.84899 | T58: 4129.85 | U58: 1723.05 | V58: 5880.25 | W58: 273.5 | X58: 27.35 | Y58: 300.85 | Z58: 4403.35 | AA58: 1750.4 | AB58: 6153.75 | AC58: 114.42163 | AD58: =+AD57+($AD$54-$AD$71)/17 -> 2772.1765 | AE58: 1150 | AF58: =+AD58+AE58 -> 3922.1765 | AG58: 100 | AH58: 10 | AI58: 110 | AJ58: 1628 | AK58: 1160 | AL58: 2788 | AM58: 13.363602 | AN58: =+AE58/AF58 -> 0.29320455 | AO58: =+U58/V58 -> 0.29302326
A59: 37591 | B59: 41507.2 | C59: 35387.2 | D59: 76921.6 | E59: 3155.2 | F59: 353.6 | G59: 3508.8 | H59: 44689.6 | I59: 35740.8 | J59: 80430.4 | K59: 7017.6 | L59: 6827.2 | M59: 13844.8 | N59: 51707.2 | O59: 42568 | P59: 94275.2 | Q59: 644.94915 | R59: 29.15058 | T59: 3971.2 | U59: 1768 | V59: 5739.2 | W59: 244.8 | X59: 54.4 | Y59: 299.2 | Z59: 4188.8 | AA59: 1822.4 | AB59: 6011.2 | AC59: 60.093615 | AD59: =+AD58+($AD$54-$AD$71)/17 -> 2849.4706 | AE59: 1236 | AF59: =+AD59+AE59 -> 4085.4706 | AG59: 107 | AH59: 11 | AI59: 118 | AJ59: 1488 | AK59: 1247 | AL59: 2735 | AM59: 21.502042 | AN59: =+AE59/AF59 -> 0.30253553 | AO59: =+U59/V59 -> 0.30805687
A60: 37622 | B60: 41220.9 | C60: 37280.25 | D60: 78501.15 | E60: 3175.2 | F60: 340.2 | G60: 3543.75 | H60: 44424.45 | I60: 37620.45 | J60: 82044.9 | K60: 7541.1 | L60: 7030.8 | M60: 14571.9 | N60: 51965.55 | O60: 44679.6 | P60: 96616.8 | Q60: -3594.5346 | R60: -191.55393 | T60: 4054.05 | U60: 1786.05 | V60: 5840.1 | W60: 255.15 | X60: 56.7 | Y60: 311.85 | Z60: 4309.2 | AA60: 1842.75 | AB60: 6151.95 | AC60: -375.102 | AD60: =+AD59+($AD$54-$AD$71)/17 -> 2926.7647 | AE60: 1251 | AF60: =+AD60+AE60 -> 4177.7647 | AG60: 103 | AH60: 11 | AI60: 114 | AJ60: 1415 | AK60: 1262 | AL60: 2677 | AM60: -113.56023 | AN60: =+AE60/AF60 -> 0.29944243 | AO60: =+U60/V60 -> 0.30582524
A61: 37653 | B61: 38988 | C61: 38703 | D61: 77691 | E61: 2764.5 | F61: 741 | G61: 3505.5 | H61: 41752.5 | I61: 39444 | J61: 81196.5 | K61: 6298.5 | L61: 8350.5 | M61: 14649 | N61: 48051 | O61: 47794.5 | P61: 95845.5 | Q61: 205.4622 | R61: 65.203149 | T61: 4018.5 | U61: 1966.5 | V61: 5985 | W61: 256.5 | X61: 57 | Y61: 313.5 | Z61: 4275 | AA61: 2023.5 | AB61: 6298.5 | AC61: 17.910877 | AD61: =+AD60+($AD$54-$AD$71)/17 -> 3004.0588 | AE61: 1288 | AF61: =+AD61+AE61 -> 4292.0588 | AG61: 89 | AH61: 24 | AI61: 113 | AJ61: 1315 | AK61: 1313 | AL61: 2628 | AM61: 6.580748 | AN61: =+AE61/AF61 -> 0.30008908 | AO61: =+U61/V61 -> 0.32857143
A62: 37681 | B62: 36356.2 | C62: 29911.5 | D62: 66267.7 | E62: 2803.3 | F62: 289 | G62: 3092.3 | H62: 39159.5 | I62: 30200.5 | J62: 69360 | K62: 6213.5 | L62: 7138.3 | M62: 13351.8 | N62: 45373 | O62: 37338.8 | P62: 82682.9 | Q62: -1762.7959 | R62: 130.11395 | T62: 4074.9 | U62: 1502.8 | V62: 5606.6 | W62: 231.2 | X62: 57.8 | Y62: 289 | Z62: 4335 | AA62: 1560.6 | AB62: 5895.6 | AC62: -260.45762 | AD62: =+AD61+($AD$54-$AD$71)/17 -> 3081.3529 | AE62: 982 | AF62: =+AD62+AE62 -> 4063.3529 | AG62: 88 | AH62: 8 | AI62: 97 | AJ62: 1205 | AK62: 991 | AL62: 2196 | AM62: -51.984023 | AN62: =+AE62/AF62 -> 0.24167234 | AO62: =+U62/V62 -> 0.26804124
A63: 37712 | B63: 36661.8 | C63: 29899.8 | D63: 66532.2 | E63: 2851.8 | F63: 294 | G63: 3145.8 | H63: 39513.6 | I63: 30193.8 | J63: 69707.4 | K63: 6379.8 | L63: 7085.4 | M63: 13465.2 | N63: 45893.4 | O63: 37279.2 | P63: 83172.6 | Q63: 679.98024 | R63: 0.1948196 | T63: 4321.8 | U63: 1528.8 | V63: 5821.2 | W63: 264.6 | X63: 58.8 | Y63: 294 | Z63: 4557 | AA63: 1558.2 | AB63: 6144.6 | AC63: 14.502803 | AD63: =+AD62+($AD$54-$AD$71)/17 -> 3158.6471 | AE63: 965 | AF63: =+AD63+AE63 -> 4123.6471 | AG63: 89 | AH63: 8 | AI63: 97 | AJ63: 1189 | AK63: 973 | AL63: 2162 | AM63: 22.635287 | AN63: =+AE63/AF63 -> 0.23401615 | AO63: =+U63/V63 -> 0.26262626
A64: 37742 | B64: 32807.3 | C64: 20052 | D64: 52859.3 | E64: 2590.05 | F64: 250.65 | G64: 2840.7 | H64: 35397.35 | I64: 20302.65 | J64: 55700 | K64: 4066.1 | L64: 3926.85 | M64: 7992.95 | N64: 39463.45 | O64: 24229.5 | P64: 63692.95 | Q64: 234.94915 | R64: 0.13791161 | T64: 3871.15 | U64: 1086.15 | V64: 4929.45 | W64: 222.8 | X64: 55.7 | Y64: 278.5 | Z64: 4093.95 | AA64: 1141.85 | AB64: 5235.8 | AC64: 27.14091 | AD64: =+AD63+($AD$54-$AD$71)/17 -> 3235.9412 | AE64: 681 | AF64: =+AD64+AE64 -> 3916.9412 | AG64: 85 | AH64: 7 | AI64: 92 | AJ64: 1124 | AK64: 688 | AL64: 1812 | AM64: 7.4616963 | AN64: =+AE64/AF64 -> 0.17386015 | AO64: =+U64/V64 -> 0.22033898
A65: 37773 | B65: 26217 | C65: 23193 | D65: 49383 | E65: 2430 | F65: 324 | G65: 2781 | H65: 28647 | I65: 23517 | J65: 52164 | K65: 3510 | L65: 2997 | M65: 6507 | N65: 32157 | O65: 26541 | P65: 58671 | Q65: 675.93734 | R65: 153.50225 | T65: 3618 | U65: 1134 | V65: 4725 | W65: 108 | X65: 135 | Y65: 243 | Z65: 3726 | AA65: 1269 | AB65: 4968 | AC65: 22.425262 | AD65: =+AD64+($AD$54-$AD$71)/17 -> 3313.2353 | AE65: 817 | AF65: =+AD65+AE65 -> 4130.2353 | AG65: 86 | AH65: 7 | AI65: 94 | AJ65: 923 | AK65: 824 | AL65: 1748 | AM65: 24.204151 | AN65: =+AE65/AF65 -> 0.19780955 | AO65: =+U65/V65 -> 0.24
A66: 37803 | B66: 27208.2 | C66: 21783 | D66: 48991.2 | E66: 2356.4 | F66: 356.2 | G66: 2712.6 | H66: 29564.6 | I66: 22139.2 | J66: 51703.8 | K66: 3370.2 | L66: 2849.6 | M66: 6219.8 | N66: 32934.8 | O66: 24988.8 | P66: 57923.6 | Q66: 248.24268 | R66: 31.106187 | T66: 3479.8 | U66: 1013.8 | V66: 4493.6 | W66: 109.6 | X66: 164.4 | Y66: 274 | Z66: 3589.4 | AA66: 1178.2 | AB66: 4767.6 | AC66: 37.511289 | AD66: =+AD65+($AD$54-$AD$71)/17 -> 3390.5294 | AE66: 758 | AF66: =+AD66+AE66 -> 4148.5294 | AG66: 82 | AH66: 7 | AI66: 89 | AJ66: 948 | AK66: 765 | AL66: 1713 | AM66: 7.6909268 | AN66: =+AE66/AF66 -> 0.18271535 | AO66: =+U66/V66 -> 0.22560976
... A70: 37926 | B70: 32252.4 | C70: 17802.4 | D70: 50054.8 | E70: 2312 | F70: 260.1 | G70: 2572.1 | H70: 34564.4 | I70: 18062.5 | J70: 52626.9 | K70: 4306.1 | L70: 1791.8 | M70: 6097.9 | N70: 38870.5 | O70: 19883.2 | P70: 58753.7 | Q70: 169.99685 | R70: 58.029061 | T70: 3121.2 | U70: 1069.3 | V70: 4190.5 | W70: 57.8 | X70: 115.6 | Y70: 173.4 | Z70: 3207.9 | AA70: 1184.9 | AB70: 4363.9 | AC70: 24.617721 | AD70: =+AD69+($AD$54-$AD$71)/17 -> 3699.7059 | AE70: 579 | AF70: =+AD70+AE70 -> 4278.7059 | AG70: 77 | AH70: 6 | AI70: 83 | AJ70: 1086 | AK70: 584 | AL70: 1670 | AM70: 5.0304197 | AN70: =+AE70/AF70 -> 0.13532129 | AO70: =+U70/V70 -> 0.25517241
A71: 37956 | B71: 36976.6 | C71: 7471.5 | D71: 44477.4 | E71: 2285.4 | F71: 58.6 | G71: 2344 | H71: 39262 | I71: 7559.4 | J71: 46792.1 | K71: 4541.5 | L71: 439.5 | M71: 4981 | N71: 43803.5 | O71: 7998.9 | P71: 51802.4 | Q71: 2111.6552 | R71: 234.26205 | T71: 3310.9 | U71: 380.9 | V71: 3721.1 | W71: 146.5 | X71: 0 | Y71: 175.8 | Z71: 3486.7 | AA71: 410.2 | AB71: 3896.9 | AC71: -150.01452 | AD71: 1149 | AE71: 242 | AF71: 1391 | AG71: 72 | AH71: 2 | AI71: 74 | AJ71: 1221 | AK71: 244 | AL71: 1465 | AM71: 77.190094 | AN71: =+AE71/AF71 -> 0.17397556 | AO71: =+U71/V71 -> 0.1023622
A72: 37987 | B72: 37308.6 | C72: 7203 | D72: 44511.6 | E72: 2205 | F72: 58.8 | G72: 2263.8 | H72: 39513.6 | I72: 7261.8 | J72: 46775.4 | K72: 3969 | L72: 441 | M72: 4380.6 | N72: 43482.6 | O72: 7702.8 | P72: 51156 | Q72: -29.619165 | R72: 266.85865 | T72: 3381 | U72: 382.2 | V72: 3763.2 | W72: 117.6 | X72: 0 | Y72: 147 | Z72: 3498.6 | AA72: 411.6 | AB72: 3910.2 | AC72: 0.29885772 | AD72: 1154 | AE72: 231 | AF72: 1386 | AG72: 71 | AH72: 2 | AI72: 72 | AJ72: 1225 | AK72: 233 | AL72: 1458 | AM72: -1.0176198 | AN72: =+AE72/AF72 -> 0.16666667 | AO72: =+U72/V72 -> 0.1015625
...

Sheet Coop.
A1: Banco Central del Uruguay | T1: Banco Central del Uruguay
A2: Superintendencia de Servicios Financieros | T2: Superintendencia de Instituciones de Intermediación Financiera
M3: Volver al Índice | AH3: Volver al Índice
B4: CRÉDITOS BRUTOS SECTOR NO FINANCIERO (SNF) (1) | T4: CRÉDITOS BRUTOS SNF (1) - ANEXO RESIDENTES POR MONEDAS
B5: COOPERATIVAS DE INTERMEDIACIÓN FINANCIERA (2) | T5: COOPERATIVAS DE INTERMEDIACIÓN FINANCIERA (2)
B6: (Crédito Total en millones de pesos) | T6: (Créditos en MN en millones de pesos y en ME en millones de dólares)
B8: TOTAL (MN + ME) en millones de pesos
B9: RESIDENTES | K9: NO RESIDENTES (5) | N9: TOTAL | Q9: Variación mensual | T9: MONEDA NACIONAL en millones de pesos | AD9: MONEDA EXTRANJERA en millones de dólares
A10: Mes | B10: SECTOR PRIVADO (3) | E10: SECTOR PÚBLICO (4) | H10: TOTAL (S.Priv. + S.Públ) | Q10: Castigados (1) | T10: SECTOR PRIVADO (3) | W10: SECTOR PÚBLICO (4) | Z10: TOTAL (S.Priv. + S.Públ) | AC10: Variac. mens. | AD10: SECTOR PRIVADO (3) | AG10: SECTOR PÚBLICO (4) | AJ10: TOTAL (S.Priv. + S.Públ) | AM10: Variac. mens.
B11: Vigentes | C11: Vencidos | D11: Total | E11: Vigentes | F11: Vencidos | G11: Total | H11: Vigentes | I11: Vencidos | J11: Total | K11: Vigentes | L11: Vencidos | M11: Total | N11: Vigentes | O11: Vencidos | P11: Total | Q11: Resid. | R11: No resid. | T11: Vigentes | U11: Vencidos | V11: Total | W11: Vigentes | X11: Vencidos | Y11: Total | Z11: Vigentes | AA11: Vencidos | AB11: Total | AC11: Castigados (1) | AD11: Vigentes | AE11: Vencidos | AF11: Total | AG11: Vigentes | AH11: Vencidos | AI11: Total | AJ11: Vigentes | AK11: Vencidos | AL11: Total | AM11: Castigados (1)
A12: 36130 | B12: 3407.355 | C12: 443.497 | D12: 3850.852 | E12: 0 | F12: 0 | G12: 0 | H12: 3407.355 | I12: 443.497 | J12: 3850.852 | K12: 10.817 | L12: 0 | M12: 10.817 | N12: 3407.355 | O12: 443.497 | P12: 3850.852 | Q12: 1.0498192 | R12: 0 | T12: 1341.308 | U12: 173.072 | V12: 1525.197 | W12: 0 | X12: 0 | Y12: 0 | Z12: 1341.308 | AA12: 173.072 | AB12: 1525.197 | AC12: -28.914457 | AD12: 190 | AE12: 25 | AF12: 215 | AG12: 0 | AH12: 0 | AI12: 0 | AJ12: 190 | AK12: 25 | AL12: 215 | AM12: 2.7701097
A13: 36161 | B13: 3301.97 | C13: 570.44 | D13: 3872.41 | E13: 0 | F13: 0 | G13: 0 | H13: 3301.97 | I13: 570.44 | J13: 3872.41 | K13: 10.97 | L13: 0 | M13: 10.97 | N13: 3312.94 | O13: 570.44 | P13: 3883.38 | Q13: 2.7633489 | R13: 0 | T13: 1305.43 | U13: 219.4 | V13: 1524.83 | W13: 0 | X13: 0 | Y13: 0 | Z13: 1305.43 | AA13: 219.4 | AB13: 1524.83 | AC13: 0.098874 | AD13: 182 | AE13: 32 | AF13: 214 | AG13: 0 | AH13: 0 | AI13: 0 | AJ13: 182 | AK13: 32 | AL13: 214 | AM13: 0.24288741
A14: 36192 | B14: 3251.56 | C14: 637.13 | D14: 3888.69 | E14: 0 | F14: 0 | G14: 0 | H14: 3251.56 | I14: 637.13 | J14: 3888.69 | K14: 10.985 | L14: 0 | M14: 10.985 | N14: 3262.545 | O14: 637.13 | P14: 3899.675 | Q14: 0.44537497 | R14: 0 | T14: 1285.245 | U14: 241.67 | V14: 1515.93 | W14: 0 | X14: 0 | Y14: 0 | Z14: 1285.245 | AA14: 241.67 | AB14: 1515.93 | AC14: 0.25195263 | AD14: 179 | AE14: 36 | AF14: 215 | AG14: 0 | AH14: 0 | AI14: 0 | AJ14: 179 | AK14: 36 | AL14: 215 | AM14: 0.01760786
A15: 36220 | B15: 3250.835 | C15: 532.56 | D15: 3794.49 | E15: 0 | F15: 0 | G15: 0 | H15: 3261.93 | I15: 532.56 | J15: 3794.49 | K15: 11.095 | L15: 0 | M15: 11.095 | N15: 3261.93 | O15: 532.56 | P15: 3805.585 | Q15: 109.76238 | R15: 0 | T15: 1264.83 | U15: 210.805 | V15: 1475.635 | W15: 0 | X15: 0 | Y15: 0 | Z15: 1264.83 | AA15: 210.805 | AB15: 1475.635 | AC15: 36.158385 | AD15: 180 | AE15: 30 | AF15: 209 | AG15: 0 | AH15: 0 | AI15: 0 | AJ15: 180 | AK15: 30 | AL15: 209 | AM15: 6.6339788
A16: 36251 | B16: 3264.899 | C16: 546.007 | D16: 3799.763 | E16: 0 | F16: 0 | G16: 0 | H16: 3264.899 | I16: 546.007 | J16: 3799.763 | K16: 11.143 | L16: 0 | M16: 11.143 | N16: 3264.899 | O16: 546.007 | P16: 3810.906 | Q16: 2.2544573 | R16: 0 | T16: 1248.016 | U16: 211.717 | V16: 1470.876 | W16: 0 | X16: 0 | Y16: 0 | Z16: 1248.016 | AA16: 211.717 | AB16: 1470.876 | AC16: 1.6706797 | AD16: 180 | AE16: 29 | AF16: 209 | AG16: 0 | AH16: 0 | AI16: 0 | AJ16: 180 | AK16: 29 | AL16: 210 | AM16: 0.052389631
A17: 36281 | B17: 3290.742 | C17: 526.071 | D17: 3816.813 | E17: 0 | F17: 0 | G17: 0 | H17: 3290.742 | I17: 526.071 | J17: 3816.813 | K17: 11.193 | L17: 0 | M17: 11.193 | N17: 3290.742 | O17: 526.071 | P17: 3828.006 | Q17: 3.8294469 | R17: 0 | T17: 1253.616 | U17: 201.474 | V17: 1455.09 | W17: 0 | X17: 0 | Y17: 0 | Z17: 1253.616 | AA17: 201.474 | AB17: 1455.09 | AC17: 2.0650431 | AD17: 182 | AE17: 29 | AF17: 211 | AG17: 0 | AH17: 0 | AI17: 0 | AJ17: 182 | AK17: 29 | AL17: 211 | AM17: 0.15763457
A18: 36312 | B18: 3308.961 | C18: 511.695 | D18: 3809.285 | E18: 0 | F18: 0 | G18: 0 | H18: 3308.961 | I18: 511.695 | J18: 3809.285 | K18: 11.371 | L18: 0 | M18: 11.371 | N18: 3308.961 | O18: 511.695 | P18: 3820.656 | Q18: 15.881818 | R18: 0 | T18: 1239.439 | U18: 193.307 | V18: 1432.746 | W18: 0 | X18: 0 | Y18: 0 | Z18: 1239.439 | AA18: 193.307 | AB18: 1432.746 | AC18: 4.220115 | AD18: 182 | AE18: 27 | AF18: 210 | AG18: 0 | AH18: 0 | AI18: 0 | AJ18: 182 | AK18: 27 | AL18: 210 | AM18: 1.0255653
A19: 36342 | B19: 3277.5 | C19: 540.5 | D19: 3818 | E19: 0 | F19: 0 | G19: 0 | H19: 3277.5 | I19: 540.5 | J19: 3818 | K19: 11.5 | L19: 0 | M19: 11.5 | N19: 3289 | O19: 540.5 | P19: 3818 | Q19: 4.7833013 | R19: 0 | T19: 1219 | U19: 195.5 | V19: 1414.5 | W19: 0 | X19: 0 | Y19: 0 | Z19: 1219 | AA19: 195.5 | AB19: 1414.5 | AC19: 2.1820533 | AD19: 179 | AE19: 29 | AF19: 208 | AG19: 0 | AH19: 0 | AI19: 0 | AJ19: 179 | AK19: 29 | AL19: 209 | AM19: 0.22619548
A20: 36373 | B20: 3289.53 | C20: 571.585 | D20: 3861.115 | E20: 0 | F20: 0 | G20: 0 | H20: 3289.53 | I20: 571.585 | J20: 3861.115 | K20: 11.665 | L20: 0 | M20: 11.665 | N20: 3301.195 | O20: 571.585 | P20: 3861.115 | Q20: 1.051732 | R20: 0 | T20: 1224.825 | U20: 209.97 | V20: 1434.795 | W20: 0 | X20: 0 | Y20: 0 | Z20: 1224.825 | AA20: 209.97 | AB20: 1434.795 | AC20: 1.6773669 | AD20: 177 | AE20: 31 | AF20: 208 | AG20: 0 | AH20: 0 | AI20: 0 | AJ20: 177 | AK20: 31 | AL20: 208 | AM20: -0.053633515
A21: 36404 | B21: 3276.46 | C21: 594.66 | D21: 3871.12 | E21: 0 | F21: 0 | G21: 0 | H21: 3288.12 | I21: 594.66 | J21: 3882.78 | K21: 11.66 | L21: 0 | M21: 11.66 | N21: 3288.12 | O21: 594.66 | P21: 3882.78 | Q21: 1.7604277 | R21: 0 | T21: 1224.3 | U21: 221.54 | V21: 1445.84 | W21: 0 | X21: 0 | Y21: 0 | Z21: 1224.3 | AA21: 221.54 | AB21: 1445.84 | AC21: 1.9298209 | AD21: 176 | AE21: 32 | AF21: 209 | AG21: 0 | AH21: 0 | AI21: 0 | AJ21: 177 | AK21: 32 | AL21: 209 | AM21: -0.014527718
A22: 36434 | B22: 3239.6 | C22: 613.21 | D22: 3864.38 | E22: 0 | F22: 0 | G22: 0 | H22: 3239.6 | I22: 613.21 | J22: 3864.38 | K22: 11.57 | L22: 0 | M22: 11.57 | N22: 3251.17 | O22: 613.21 | P22: 3864.38 | Q22: 2.4352389 | R22: 0 | T22: 1203.28 | U22: 219.83 | V22: 1423.11 | W22: 0 | X22: 0 | Y22: 0 | Z22: 1203.28 | AA22: 219.83 | AB22: 1423.11 | AC22: 1.8325349 | AD22: 176 | AE22: 34 | AF22: 210 | AG22: 0 | AH22: 0 | AI22: 0 | AJ22: 176 | AK22: 34 | AL22: 210 | AM22: 0.052091958
A23: 36465 | B23: 3268.367 | C23: 612.097 | D23: 3880.464 | E23: 0 | F23: 0 | G23: 0 | H23: 3268.367 | I23: 612.097 | J23: 3880.464 | K23: 0 | L23: 0 | M23: 0 | N23: 3279.916 | O23: 612.097 | P23: 3880.464 | Q23: 2.4687968 | R23: 0 | T23: 1212.645 | U23: 219.431 | V23: 1432.076 | W23: 0 | X23: 0 | Y23: 0 | Z23: 1212.645 | AA23: 219.431 | AB23: 1432.076 | AC23: 2.7873573 | AD23: 178 | AE23: 34 | AF23: 212 | AG23: 0 | AH23: 0 | AI23: 0 | AJ23: 178 | AK23: 34 | AL23: 212 | AM23: -0.027583387
... A251: 43405 | B251: 444.04156 | C251: 75.881692 | D251: 519.92325 | E251: 21.233584 | F251: 0 | G251: 21.233584 | H251: 465.27514 | I251: 75.881692 | J251: 541.15684 | K251: 0 | L251: 0 | M251: 0 | N251: 465.27514 | O251: 75.881692 | P251: 541.15684 | Q251: 0.24601731 | R251: 0 | T251: 439.7633 | U251: 75.862974 | V251: 515.62627 | W251: 21.233584 | X251: 0 | Y251: 21.233584 | Z251: 460.99688 | AA251: 75.862974 | AB251: 536.85986 | AC251: 0 | AD251: 0.13294374 | AE251: 0.00058164 | AF251: 0.13352538 | AG251: 0 | AH251: 0 | AI251: 0 | AJ251: 0.13294374 | AK251: 0.00058164 | AL251: 0.13352538 | AM251: 0.0076448
A252: =+'Bcos. Públ.'!A252 -> 43435 | B252: 442.75096 | C252: 72.442606 | D252: 515.19356 | E252: 21.314396 | F252: 0 | G252: 21.314396 | H252: 464.06536 | I252: 72.442606 | J252: 536.50796 | K252: 0 | L252: 0 | M252: 0 | N252: 464.06536 | O252: 72.442606 | P252: 536.50796 | Q252: 0.18144489 | R252: 0 | T252: 438.23066 | U252: 72.429847 | V252: 510.66051 | W252: 21.314396 | X252: 0 | Y252: 21.314396 | Z252: 459.54506 | AA252: 72.429847 | AB252: 531.9749 | AC252: 0 | AD252: 0.1395585 | AE252: 0.00039391 | AF252: =+AE252+AD252 -> 0.13995241 | AG252: 0 | AH252: 0 | AI252: =+AH252+AG252 -> 0 | AJ252: 0.1395585 | AK252: 0.00039391 | AL252: =+AK252+AJ252 -> 0.13995241 | AM252: 0.00560188
A253: =+'Bcos. Públ.'!A253 -> 43467 | B253: 441.56094 | C253: 0 | D253: 441.56094 | E253: 0 | F253: 0 | G253: 0 | H253: 441.56094 | I253: 0 | J253: 441.56094 | K253: 0 | L253: 0 | M253: 0 | N253: 441.56094 | O253: 0 | P253: 441.56094 | Q253: ND | R253: ND | T253: 441.56094 | U253: 0 | V253: 441.56094 | W253: 0 | X253: 0 | Y253: 0 | Z253: 441.56094 | AA253: 0 | AB253: 441.56094 | AC253: ND | AD253: 0 | AE253: 0 | AF253: 0 | AG253: 0 | AH253: 0 | AI253: 0 | AJ253: 0 | AK253: 0 | AL253: 0 | AM253: ND
A254: 43497 | B254: 458.46107 | C254: 67.459012 | D254: 525.92008 | E254: 21.641405 | F254: 0 | G254: 21.641405 | H254: 480.10247 | I254: 67.459012 | J254: 547.56148 | K254: 0 | L254: 0 | M254: 0 | N254: 480.10247 | O254: 67.459012 | P254: 547.56148 | Q254: ND | R254: ND | T254: 454.35415 | U254: 67.452189 | V254: 521.80634 | W254: 21.641405 | X254: 0 | Y254: 21.641405 | Z254: 475.99556 | AA254: 67.452189 | AB254: 543.44774 | AC254: ND | AD254: 0.12578224 | AE254: 0.00020898 | AF254: 0.12599122 | AG254: 0 | AH254: 0 | AI254: 0 | AJ254: 0.12578224 | AK254: 0.00020898 | AL254: 0.12599122 | AM254: ND
A255: 43525 | B255: 462.09808 | C255: 69.054489 | D255: 531.15257 | E255: 21.912785 | F255: 0 | G255: 21.912785 | H255: 484.01086 | I255: 69.054489 | J255: 553.06535 | K255: 0 | L255: 0 | M255: 0 | N255: 484.01086 | O255: 69.054489 | P255: 553.06535 | Q255: ND | R255: ND | T255: 457.43625 | U255: 69.047492 | V255: 526.48375 | W255: 21.912785 | X255: 0 | Y255: 21.912785 | Z255: 479.34904 | AA255: 69.047492 | AB255: 548.39653 | AC255: ND | AD255: 0.13922541 | AE255: 0.00020898 | AF255: 0.13943439 | AG255: 0 | AH255: 0 | AI255: 0 | AJ255: 0.13922541 | AK255: 0.00020898 | AL255: 0.13943439 | AM255: ND
A256: 43556 | B256: 455.26372 | C256: 79.709991 | D256: 534.97371 | E256: 22.057074 | F256: 0 | G256: 22.057074 | H256: 477.32079 | I256: 79.709991 | J256: 557.03078 | K256: 0 | L256: 0 | M256: 0 | N256: 477.32079 | O256: 79.709991 | P256: 557.03078 | Q256: ND | R256: ND | T256: 450.63285 | U256: 79.702681 | V256: 530.33553 | W256: 22.057074 | X256: 0 | Y256: 22.057074 | Z256: 472.68992 | AA256: 79.702681 | AB256: 552.3926 | AC256: ND | AD256: 0.13238244 | AE256: 0.00020898 | AF256: 0.13259142 | AG256: 0 | AH256: 0 | AI256: 0 | AJ256: 0.13238244 | AK256: 0.00020898 | AL256: 0.13259142 | AM256: ND
A257: 43586 | B257: 458.39217 | C257: 79.438577 | D257: 537.83074 | E257: 22.165939 | F257: 0 | G257: 22.165939 | H257: 480.55811 | I257: 79.438577 | J257: 559.99668 | K257: 0 | L257: 0 | M257: 0 | N257: 480.55811 | O257: 79.438577 | P257: 559.99668 | Q257: ND | R257: ND | T257: 453.56086 | U257: 79.43121 | V257: 532.99207 | W257: 22.165939 | X257: 0 | Y257: 22.165939 | Z257: 475.7268 | AA257: 79.43121 | AB257: 555.15801 | AC257: ND | AD257: 0.13705056 | AE257: 0.00020898 | AF257: 0.13725954 | AG257: 0 | AH257: 0 | AI257: 0 | AJ257: 0.13705056 | AK257: 0.00020898 | AL257: 0.13725954 | AM257: ND
A258: 43617 | B258: 455.28596 | C258: 81.141587 | D258: 536.42755 | E258: 22.264275 | F258: 0 | G258: 22.264275 | H258: 477.55024 | I258: 81.141587 | J258: 558.69182 | K258: 0 | L258: 0 | M258: 0 | N258: 477.55024 | O258: 81.141587 | P258: 558.69182 | Q258: ND | R258: ND | T258: 448.97404 | U258: 81.134235 | V258: 530.10827 | W258: 22.264275 | X258: 0 | Y258: 22.264275 | Z258: 471.23831 | AA258: 81.134235 | AB258: 552.37254 | AC258: ND | AD258: 0.17940783 | AE258: 0.00020898 | AF258: 0.17961681 | AG258: 0 | AH258: 0 | AI258: 0 | AJ258: 0.17940783 | AK258: 0.00020898 | AL258: 0.17961681 | AM258: ND
A259: 43647 | B259: 452.70112 | C259: 82.998551 | D259: 535.69967 | E259: 22.296369 | F259: 0 | G259: 22.296369 | H259: 474.99749 | I259: 82.998551 | J259: 557.99604 | K259: 0 | L259: 0 | M259: 0 | N259: 474.99749 | O259: 82.998551 | P259: 557.99604 | Q259: ND | R259: ND | T259: 446.39657 | U259: 82.991372 | V259: 529.38795 | W259: 22.296369 | X259: 0 | Y259: 22.296369 | Z259: 468.69294 | AA259: 82.991372 | AB259: 551.68432 | AC259: ND | AD259: 0.18353837 | AE259: 0.00020898 | AF259: 0.18374735 | AG259: 0 | AH259: 0 | AI259: 0 | AJ259: 0.18353837 | AK259: 0.00020898 | AL259: 0.18374735 | AM259: ND
A260: 43678 | B260: 455.00827 | C260: 86.277769 | D260: 541.28604 | E260: 22.471047 | F260: 0 | G260: 22.471047 | H260: 477.47932 | I260: 86.277769 | J260: 563.75709 | K260: 0 | L260: 0 | M260: 0 | N260: 477.47932 | O260: 86.277769 | P260: 563.75709 | Q260: ND | R260: ND | T260: 447.74821 | U260: 86.270112 | V260: 534.01833 | W260: 22.471047 | X260: 0 | Y260: 22.471047 | Z260: 470.21926 | AA260: 86.270112 | AB260: 556.48937 | AC260: ND | AD260: 0.19813491 | AE260: 0.00020898 | AF260: 0.19834389 | AG260: 0 | AH260: 0 | AI260: 0 | AJ260: 0.19813491 | AK260: 0.00020898 | AL260: 0.19834389 | AM260: ND
A261: 43709 | B261: 468.13799 | C261: 91.766621 | D261: 559.90461 | E261: 22.672823 | F261: 0 | G261: 22.672823 | H261: 490.81082 | I261: 91.766621 | J261: 582.57744 | K261: 0 | L261: 0 | M261: 0 | N261: 490.81082 | O261: 91.766621 | P261: 582.57744 | Q261: ND | R261: ND | T261: 461.25758 | U261: 91.758901 | V261: 553.01648 | W261: 22.672823 | X261: 0 | Y261: 22.672823 | Z261: 483.9304 | AA261: 91.758901 | AB261: 575.6893 | AC261: ND | AD261: 0.18626422 | AE261: 0.00020898 | AF261: 0.1864732 | AG261: 0 | AH261: 0 | AI261: 0 | AJ261: 0.18626422 | AK261: 0.00020898 | AL261: 0.1864732 | AM261: ND
A262: 43739 | B262: 491.3816 | C262: 87.288885 | D262: 578.67049 | E262: 22.81447 | F262: 0 | G262: 22.81447 | H262: 514.19607 | I262: 87.288885 | J262: 601.48496 | K262: 0 | L262: 0 | M262: 0 | N262: 514.19607 | O262: 87.288885 | P262: 601.48496 | Q262: ND | R262: ND | T262: 483.66325 | U262: 87.281065 | V262: 570.94432 | W262: 22.81447 | X262: 0 | Y262: 22.81447 | Z262: 506.47772 | AA262: 87.281065 | AB262: 593.75879 | AC262: ND | AD262: 0.20628477 | AE262: 0.00020898 | AF262: 0.20649375 | AG262: 0 | AH262: 0 | AI262: 0 | AJ262: 0.20628477 | AK262: 0.00020898 | AL262: 0.20649375 | AM262: ND
A263: 43770 | B263: 506.66592 | C263: 88.777222 | D263: 595.44314 | E263: 22.980035 | F263: 0 | G263: 22.980035 | H263: 529.64596 | I263: 88.777222 | J263: 618.42318 | K263: 0 | L263: 0 | M263: 0 | N263: 529.64596 | O263: 88.777222 | P263: 618.42318 | Q263: ND | R263: ND | T263: 499.02056 | U263: 88.769314 | V263: 587.78988 | W263: 22.980035 | X263: 0 | Y263: 22.980035 | Z263: 522.0006 | AA263: 88.769314 | AB263: 610.76991 | AC263: ND | AD263: 0.20204439 | AE263: 0.00020898 | AF263: 0.20225337 | AG263: 0 | AH263: 0 | AI263: 0 | AJ263: 0.20204439 | AK263: 0.00020898 | AL263: 0.20225337 | AM263: ND
A264: 43800 | B264: 509.72208 | C264: 85.890201 | D264: 595.61228 | E264: 23.104974 | F264: 0 | G264: 23.104974 | H264: 532.82706 | I264: 85.890201 | J264: 618.71726 | K264: 0 | L264: 0 | M264: 0 | N264: 532.82706 | O264: 85.890201 | P264: 618.71726 | Q264: ND | R264: ND | T264: 503.25064 | U264: 85.890201 | V264: 589.14084 | W264: 23.104974 | X264: 0 | Y264: 23.104974 | Z264: 526.35561 | AA264: 85.890201 | AB264: 612.24582 | AC264: ND | AD264: 0.17332985 | AE264: 0 | AF264: 0.17332985 | AG264: 0 | AH264: 0 | AI264: 0 | AJ264: 0.17332985 | AK264: 0 | AL264: 0.17332985 | AM264: ND
A265: 43831 | B265: 518.47651 | C265: 87.045043 | D265: 605.52156 | E265: 23.124638 | F265: 0 | G265: 23.124638 | H265: 541.60115 | I265: 87.045043 | J265: 628.64619 | K265: 0 | L265: 0 | M265: 0 | N265: 541.60115 | O265: 87.045043 | P265: 628.64619 | Q265: ND | R265: ND | T265: 511.57943 | U265: 87.045043 | V265: 598.62448 | W265: 23.124638 | X265: 0 | Y265: 23.124638 | Z265: 534.70407 | AA265: 87.045043 | AB265: 621.74912 | AC265: ND | AD265: 0.18377015 | AE265: 0 | AF265: 0.18377015 | AG265: 0 | AH265: 0 | AI265: 0 | AJ265: 0.18377015 | AK265: 0 | AL265: 0.18377015 | AM265: ND
